Workbook

Sheet 00_Инструкция
A1: Как читать доказательный реестр
A4: Цель | B4: Показать: 1) соответствие Программы развития требованиям государственных органов; 2) обеспечение требований Планом мероприятий; 3) согласованность Программы и Плана; 4) исполнение KPI за 2025 год.
A5: 01_Требования_госорганов | B5: Полный реестр внешних требований, показателей, нормативных требований и поручений. Значения по годам переносятся только из внешнего документа.
A6: 02_Программа_развития | B6: Все 65 KPI университета, включая собственные цели, не связанные напрямую с внешними требованиями. Здесь же показано обеспечение Планом. Подробный анализ исполнения за 2025 год вынесен в отдельный лист «05_Отчёт_2025».
A7: 03_План_мероприятий | B7: Полный перечень мероприятий Программы развития: срок, форма завершения, плановые значения и ответственный. Отдельной графы финансирования в утверждённом Плане нет; источник и объём средств запрашиваются дополнительно.
A8: 04_Анализ_соответствия | B8: Сквозной анализ по каждой записи: требование госоргана — KPI Программы — мероприятие Плана — значения 2023–2029 — сравнение плана и факта за 2025 год — положение факта относительно целей 2026–2029 — пробел — управленческое действие. Факт 2025 не изменяет утверждённые будущие значения без отдельного решения.
A9: Подтверждённая связь | B9: Связь считается установленной только при наличии проверяемого ID требования, KPI Программы и кода мероприятия. Сходство формулировок без документальной связи не считается соответствием.
A10: Формальная цепочка | B10: Дашборд разделяет внешние требования, собственные KPI университета, обеспеченность мероприятиями и факт за 2025 год. График по годам показывает наличие установленных значений, но не подменяет проверку сопоставимости единиц и содержания показателей.
A11: Пустые годовые ячейки | B11: Не означают ноль. Они означают, что значение в документе не установлено, год не относится к периоду либо запись не является числовым показателем. Причина раскрывается в статусе и аналитическом комментарии.
A12: Факт 2025 | B12: Переносится только при совпадении объекта, единицы, периода и формулы. Расчётные факты отдельно помечены. Если сопоставимость не подтверждена, KPI не считается выполненным или невыполненным.
A13: Национальные показатели | B13: Не являются KPI университета без утверждённой декомпозиции и индивидуального значения Abai University.
A14: Собственные цели | B14: Если связь с внешним требованием не установлена, KPI не удаляется: он отражается как собственная цель университета либо как связь, требующая дополнительного подтверждения.
A15: Цвет | B15: Подтверждено / достигнуто | C15: Частично / требуется проверка | D15: Установлен пробел / не достигнуто | E15: Оценка невозможна
A16: Источники | B16: Лист содержит один документ в одной строке. Для источников, охватывающих несколько направлений, отдельно указаны тип охвата и полный перечень направлений. Основное направление не назначается, если оно не определено документом.
A18: Навигация по мероприятиям: в листе «04_Анализ_соответствия» нажмите «Открыть: N» в столбце AZ. Откроется лист «08_Навигация_мероприятий», где каждое мероприятие имеет отдельную ссылку на соответствующую строку Плана.
A31: Итоговая инструкция к доказательному реестру
A32: Рекомендуемый порядок чтения | C32: 1) 07_Дашборд — общие факты и пробелы; 2) 04_Анализ_соответствия — сквозная цепочка; 3) 09_Пояснения_KPI — пояснение каждого KPI; 4) 10_Внешние_без_связи — внешние записи без подтверждённой связи; 5) 11_Контроль_мероприятий — годовые результаты и запросы; 6) 05_Отчёт_2025 — исторический факт; 7) 06_Источники.
A33: Зелёная строка | C33: Подтверждённый положительный результат или подтверждённая полнота плановых данных. На листе контроля мероприятий зелёный цвет не означает исполнение мероприятия.
A34: Жёлтая строка | C34: Связь или данные частичны; требуется декомпозиция, проверка применимости либо подтверждение сопоставимости.
A35: Красная строка | C35: Установлен конкретный пробел: KPI не достигнут, связанное мероприятие не найдено либо прямое/совместное внешнее требование не отражено в Программе.
A36: Серая строка | C36: Оценка невозможна по представленным документам: например, отсутствует числовой факт или запись является аналитическим ориентиром.
A37: Переход к KPI | C37: Это активная ссылка. Нажатие открывает строку соответствующего KPI на листе 09_Пояснения_KPI; значение KPI не изменяется.
A38: Как читать «без связи» | C38: Фраза означает: в представленных документах не найден KPI Программы, который можно документально связать с внешним требованием. Она не означает автоматического невыполнения.
A39: Факт 2025 | C39: Отделён от плановых значений и используется как исторический факт. Если единица, определение или методика не совпадают, результат помечается как требующий проверки, а не как достигнутый/не достигнутый.
A40: Запрет на вывод без доказательства | C40: Пустое значение не заменяется предположением. В реестре используется формулировка «не найдено/не подтверждено в представленных документах».

Sheet 01_Требования_госорганов
A1: Реестр требований государственных органов и внешних ориентиров
A2: № | B2: ID требования | C2: Направление | D2: Тип записи | E2: Требование / показатель / поручение | F2: Документ | G2: Источник ID | H2: Точное место | I2: Цитата-якорь | J2: Уровень | K2: Обязательность | L2: Применимость к Abai | M2: Вклад Abai / декомпозиция | N2: Единица | O2: 2023 | P2: 2024 | Q2: 2025 | R2: 2026 | S2: 2027 | T2: 2028 | U2: 2029 | V2: 2030 | W2: Статус проверки
A3: 1 | B3: K002 | C3: Образование | D3: Показатель | E3: Количество казахстанских вузов в топ-700 рейтинга QS World University Rankings | F3: Ключевые прказатели МНВО.docx | G3: D04 | H3: Таблица 1, показатель №1 («Количество казахстанских вузов в топ-700 рейтинга QS World University Rankings»); значения 2024–2030 | I3: Количество казахстанских вузов в топ-700 рейтинга QS World University Rankings | J3: Национальный | K3: Национальный/отраслевой показатель | L3: Требуется декомпозиция | M3: Указать после подтверждения индивидуального значения | N3: ед. | P3: 6 | Q3: 7 | R3: 8 | S3: 9 | T3: 10 | U3: 11 | V3: 12 | W3: Сверено с таблицей первоисточника
A4: 2 | B4: K004 | C4: Образование | D4: Показатель | E4: Количество казахстанских вузов, вошедших в рейтинг QS WUR | F4: Ключевые прказатели МНВО.docx | G4: D04 | H4: Таблица 1, показатель №3 («Количество казахстанских вузов, вошедших в рейтинг QS WUR»); значения 2024–2030 | I4: Количество казахстанских вузов, вошедших в рейтинг QS WUR | J4: Национальный | K4: Национальный/отраслевой показатель | L4: Требуется декомпозиция | M4: Указать после подтверждения индивидуального значения | N4: ед. | P4: 21 | Q4: 22 | R4: 23 | S4: 24 | T4: 25 | U4: 26 | V4: 27 | W4: Сверено с таблицей первоисточника
A5: 3 | B5: K005 | C5: Образование | D5: Показатель | E5: Доля обновленных образовательных программ вузов с учетом профессиональных стандартов | F5: Ключевые прказатели МНВО.docx | G5: D04 | H5: Таблица 1, показатель №4 («Доля обновленных образовательных программ вузов с учетом профессиональных стандартов»); значения 2024–2030 | I5: Доля обновленных образовательных программ вузов с учетом профессиональных стандартов | J5: Национальный | K5: Национальный/отраслевой показатель | L5: Требуется декомпозиция | M5: Указать после подтверждения индивидуального значения | N5: % | P5: 75.8 | Q5: 77 | R5: 80 | S5: 85 | T5: 90 | U5: 95 | V5: 97 | W5: Сверено с таблицей первоисточника
A6: 4 | B6: K006 | C6: Образование | D6: Показатель | E6: Доля организаций высшего и послевузовского образования, создавших условия для инклюзивного образования | F6: Ключевые прказатели МНВО.docx | G6: D04 | H6: Таблица 1, показатель №5 («Доля организаций высшего и послевузовского образования, создавших условия для инклюзивного»); значения 2024–2030 | I6: Доля организаций высшего и послевузовского образования, создавших условия для инклюзивного образования | J6: Национальный | K6: Национальный/отраслевой показатель | L6: Требуется декомпозиция | M6: Указать после подтверждения индивидуального значения | N6: % | P6: 70 | Q6: 80 | R6: 100 | S6: 100 | T6: 100 | U6: 100 | V6: 100 | W6: Сверено с таблицей первоисточника
A7: 5 | B7: K007 | C7: Образование | D7: Показатель | E7: Доля обучающихся, вовлеченных в организованную общественную деятельность, в том числе через студенческое самоуправление и дебатное движение с целью повышения уровня гражданственности и патриотизма | F7: Ключевые прказатели МНВО.docx | G7: D04 | H7: Таблица 1, показатель №6 («Доля обучающихся, вовлеченных в организованную общественную деятельность, в том числе чере»); значения 2024–2030 | I7: Доля обучающихся, вовлеченных в организованную общественную деятельность, в том числе через студенческое самоуправление и дебатное движение с целью повышения уровня гражданственности и патриотизма | J7: Национальный | K7: Национальный/отраслевой показатель | L7: Требуется декомпозиция | M7: Указать после подтверждения индивидуального значения | N7: % | P7: 40 | Q7: 45 | R7: 50 | S7: 55 | T7: 60 | U7: 65 | V7: 70 | W7: Сверено с таблицей первоисточника
A8: 6 | B8: K008 | C8: Образование | D8: Показатель | E8: Доля отрабатывающих выпускников в первый год после окончания ОВПО | F8: Ключевые прказатели МНВО.docx | G8: D04 | H8: Таблица 1, показатель №7 («Доля отрабатывающих выпускников в первый год после окончания ОВПО»); значения 2024–2030 | I8: Доля отрабатывающих выпускников в первый год после окончания ОВПО | J8: Национальный | K8: Национальный/отраслевой показатель | L8: Требуется декомпозиция | M8: Указать после подтверждения индивидуального значения | N8: % | P8: 40 | Q8: 41 | R8: 42 | S8: 43 | T8: 44 | U8: 45 | V8: 46 | W8: Сверено с таблицей первоисточника
A9: 7 | B9: K009 | C9: Образование | D9: Показатель | E9: Количество введенных койко-мест общежитий | F9: Ключевые прказатели МНВО.docx | G9: D04 | H9: Таблица 1, показатель №8 («Количество введенных койко-мест общежитий»); значения 2024–2030 | I9: Количество введенных койко-мест общежитий | J9: Национальный | K9: Национальный/отраслевой показатель | L9: Требуется декомпозиция | M9: Указать после подтверждения индивидуального значения | N9: место | P9: 11079 | Q9: 10000 | R9: 10000 | S9: 10000 | T9: 10000 | U9: 10000 | V9: 10000 | W9: Сверено с таблицей первоисточника
A10: 8 | B10: K011 | C10: Образование | D10: Показатель | E10: Доля вузов, охваченных специальными предметами, курсами в сфере интеллектуальной собственности | F10: Ключевые прказатели МНВО.docx | G10: D04 | H10: Таблица 1, показатель №10 («Доля вузов, охваченных специальными предметами, курсами в сфере интеллектуальной собственн»); значения 2024–2030 | I10: Доля вузов, охваченных специальными предметами, курсами в сфере интеллектуальной собственности | J10: Национальный | K10: Национальный/отраслевой показатель | L10: Требуется декомпозиция | M10: Указать после подтверждения индивидуального значения | N10: % | P10: ‒ | Q10: 3 | R10: 6 | S10: 7 | T10: 8 | U10: 9 | V10: 10 | W10: Сверено с таблицей первоисточника
A11: 9 | B11: K096 | C11: Образование | D11: Показатель | E11: Актуализированные НПА в сфере педагогического образования | F11: 0707_План действий -рус.docx | G11: D02 | H11: Целевой индикатор 1; строка определяется по формулировке «Актуализированные НПА в сфере педагогического образования» | I11: Актуализированные НПА в сфере педагогического образования | J11: Национальный | K11: Требование/мероприятие применимо к ОВПО | L11: Прямая или совместная | N11: % | S11: 40 | T11: 100 | U11: 100 | V11: 100 | W11: Сверено с первоисточником: формулировка реестра не подтверждена дословно; требуется уточнение
A12: 10 | B12: K097 | C12: Образование | D12: Показатель | E12: Образовательные программы на основе школоцентричной и практикоориентированной модели | F12: 0707_План действий -рус.docx | G12: D02 | H12: Целевой индикатор 2; строка определяется по формулировке «Образовательные программы на основе школоцентричной и практикоориентированной модели» | I12: Образовательные программы на основе школоцентричной и практикоориентированной модели | J12: Национальный | K12: Требование/мероприятие применимо к ОВПО | L12: Прямая или совместная | N12: % | S12: 20 | T12: 50 | U12: 80 | V12: 100 | W12: Сверено с первоисточником: формулировка реестра не подтверждена дословно; требуется уточнение
A13: 11 | B13: K098 | C13: Образование | D13: Показатель | E13: Образовательные программы, интегрирующие ИИ и цифровую педагогику | F13: 0707_План действий -рус.docx | G13: D02 | H13: Целевой индикатор 3; строка определяется по формулировке «Образовательные программы, интегрирующие ИИ и цифровую педагогику» | I13: Образовательные программы, интегрирующие ИИ и цифровую педагогику | J13: Национальный | K13: Требование/мероприятие применимо к ОВПО | L13: Прямая или совместная | N13: % | S13: 20 | T13: 50 | U13: 80 | V13: 100 | W13: Сверено с первоисточником: формулировка реестра не подтверждена дословно; требуется уточнение
A14: 12 | B14: K099 | C14: Образование | D14: Показатель | E14: Педагогические вузы, применяющие Learning Analytics и ИИ | F14: 0707_План действий -рус.docx | G14: D02 | H14: Целевой индикатор 4; строка определяется по формулировке «Педагогические вузы, применяющие Learning Analytics и ИИ» | I14: Педагогические вузы, применяющие Learning Analytics и ИИ | J14: Национальный | K14: Требование/мероприятие применимо к ОВПО | L14: Прямая или совместная | N14: % | S14: 20 | T14: 40 | U14: 70 | V14: 100 | W14: Сверено с первоисточником: формулировка реестра не подтверждена дословно; требуется уточнение
A15: 13 | B15: K100 | C15: Образование | D15: Показатель | E15: Педагогические вузы с международными программами, мобильностью и совместными проектами | F15: 0707_План действий -рус.docx | G15: D02 | H15: Целевой индикатор 5; строка определяется по формулировке «Педагогические вузы с международными программами, мобильностью и совместными проектами» | I15: Педагогические вузы с международными программами, мобильностью и совместными проектами | J15: Национальный | K15: Требование/мероприятие применимо к ОВПО | L15: Прямая или совместная | N15: % | S15: 40 | T15: 50 | U15: 60 | V15: 70 | W15: Сверено с первоисточником: формулировка реестра не подтверждена дословно; требуется уточнение
A16: 14 | B16: K102 | C16: Образование | D16: Показатель | E16: ППС педагогических вузов, прошедший повышение квалификации и стажировки | F16: 0707_План действий -рус.docx | G16: D02 | H16: Целевой индикатор 7; строка определяется по формулировке «ППС педагогических вузов, прошедший повышение квалификации и стажировки» | I16: ППС педагогических вузов, прошедший повышение квалификации и стажировки | J16: Национальный | K16: Требование/мероприятие применимо к ОВПО | L16: Прямая или совместная | N16: % | S16: 40 | T16: 55 | U16: 70 | V16: 80 | W16: Сверено с первоисточником: формулировка реестра не подтверждена дословно; требуется уточнение
A17: 15 | B17: K105 | C17: Образование | D17: Показатель | E17: Вузы РК в ТОП-700 QS WUR | F17: прил 1 рус.pdf | G17: D07 | H17: Таблица «Направления, цели, целевые индикаторы…», строка 1, стр. 2 | I17: Вузы РК в ТОП-700 QS WUR | J17: Национальный | K17: Национальный/отраслевой показатель | L17: Требуется декомпозиция | M17: Указать после подтверждения индивидуального значения | N17: ед. | R17: 8 | S17: 9 | W17: Сверено с первоисточником; формулировка сокращена без изменения содержания
A18: 16 | B18: K106 | C18: Образование | D18: Показатель | E18: Казахстанские вузы в рейтинге QS WUR | F18: прил 1 рус.pdf | G18: D07 | H18: Таблица «Направления, цели, целевые индикаторы…», строка 2, стр. 2 | I18: Казахстанские вузы в рейтинге QS WUR | J18: Национальный | K18: Национальный/отраслевой показатель | L18: Требуется декомпозиция | M18: Указать после подтверждения индивидуального значения | N18: ед. | R18: 23 | S18: 24 | W18: Сверено с первоисточником; формулировка сокращена без изменения содержания
A19: 17 | B19: K108 | C19: Образование | D19: Показатель | E19: Доля двудипломных образовательных программ | F19: прил 1 рус.pdf | G19: D07 | H19: Таблица «Направления, цели, целевые индикаторы…», строка 6, стр. 2 | I19: Доля двудипломных образовательных программ | J19: Национальный | K19: Национальный/отраслевой показатель | L19: Требуется декомпозиция | M19: Указать после подтверждения индивидуального значения | N19: % | R19: 55 | S19: 60 | W19: Сверено с первоисточником; формулировка сокращена без изменения содержания
A20: 18 | B20: K117 | C20: Образование | D20: Показатель | E20: Вузы, внедрившие курс по интеллектуальной собственности | F20: прил 1 рус.pdf | G20: D07 | H20: Таблица «Направления, цели, целевые индикаторы…», строка 21, стр. 4 | I20: Вузы, внедрившие курс по интеллектуальной собственности | J20: Национальный | K20: Национальный/отраслевой показатель | L20: Требуется декомпозиция | M20: Указать после подтверждения индивидуального значения | N20: ед. | R20: 6 | S20: 7 | W20: Сверено с первоисточником; формулировка сокращена без изменения содержания
A21: 19 | B21: K131 | C21: Образование | D21: Показатель | E21: Дефицит педагогических кадров в дошкольных организациях | F21: Комплексный план 3.06.26.docx | G21: D05 | H21: Сводные целевые показатели, позиция 1; строка определяется по формулировке «Дефицит педагогических кадров в дошкольных организациях» | I21: Дефицит педагогических кадров в дошкольных организациях | J21: Национальный/секторный | K21: Национальный/отраслевой показатель | L21: Требуется декомпозиция | M21: Указать после подтверждения индивидуального значения | N21: % | R21: 16 | S21: 15 | T21: 14 | W21: Сверено с первоисточником: формулировка реестра не подтверждена дословно; требуется уточнение
A22: 20 | B22: K132 | C22: Образование | D22: Показатель | E22: Доля молодых специалистов в дошкольных организациях | F22: Комплексный план 3.06.26.docx | G22: D05 | H22: Сводные целевые показатели, позиция 2; строка определяется по формулировке «Доля молодых специалистов в дошкольных организациях» | I22: Доля молодых специалистов в дошкольных организациях | J22: Национальный/секторный | K22: Национальный/отраслевой показатель | L22: Требуется декомпозиция | M22: Указать после подтверждения индивидуального значения | N22: % | R22: 32.3 | S22: 33.9 | T22: 35.5 | W22: Сверено с первоисточником: формулировка реестра не подтверждена дословно; требуется уточнение
A23: 21 | B23: K133 | C23: Образование | D23: Показатель | E23: Дошкольные педагоги с квалификацией | F23: Комплексный план 3.06.26.docx | G23: D05 | H23: Сводные целевые показатели, позиция 3; строка определяется по формулировке «Дошкольные педагоги с квалификацией» | I23: Дошкольные педагоги с квалификацией | J23: Национальный/секторный | K23: Национальный/отраслевой показатель | L23: Требуется декомпозиция | M23: Указать после подтверждения индивидуального значения | N23: % | R23: 44 | S23: 46 | T23: 48 | W23: Сверено с первоисточником: формулировка реестра не подтверждена дословно; требуется уточнение
A24: 22 | B24: K134 | C24: Образование | D24: Показатель | E24: Дошкольные педагоги с профильным образованием | F24: Комплексный план 3.06.26.docx | G24: D05 | H24: Сводные целевые показатели, позиция 4; строка определяется по формулировке «Дошкольные педагоги с профильным образованием» | I24: Дошкольные педагоги с профильным образованием | J24: Национальный/секторный | K24: Национальный/отраслевой показатель | L24: Требуется декомпозиция | M24: Указать после подтверждения индивидуального значения | N24: % | R24: 87 | S24: 88.2 | T24: 90 | W24: Сверено с первоисточником: формулировка реестра не подтверждена дословно; требуется уточнение
A25: 23 | B25: K135 | C25: Образование | D25: Показатель | E25: Охват дошкольных педагогов повышением квалификации | F25: Комплексный план 3.06.26.docx | G25: D05 | H25: Сводные целевые показатели, позиция 5; строка определяется по формулировке «Охват дошкольных педагогов повышением квалификации» | I25: Охват дошкольных педагогов повышением квалификации | J25: Национальный/секторный | K25: Национальный/отраслевой показатель | L25: Требуется декомпозиция | M25: Указать после подтверждения индивидуального значения | N25: % | R25: 68.9 | S25: 74.1 | T25: 79.3 | W25: Сверено с первоисточником: формулировка реестра не подтверждена дословно; требуется уточнение
A26: 24 | B26: K136 | C26: Образование | D26: Показатель | E26: Учителя начальных классов с высшим педагогическим образованием | F26: Комплексный план 3.06.26.docx | G26: D05 | H26: Сводные целевые показатели, позиция 6; строка определяется по формулировке «Учителя начальных классов с высшим педагогическим образованием» | I26: Учителя начальных классов с высшим педагогическим образованием | J26: Национальный/секторный | K26: Национальный/отраслевой показатель | L26: Требуется декомпозиция | M26: Указать после подтверждения индивидуального значения | N26: % | R26: 91 | S26: 93 | T26: 95 | W26: Сверено с первоисточником: формулировка реестра не подтверждена дословно; требуется уточнение
A27: 25 | B27: K137 | C27: Образование | D27: Показатель | E27: Охват учителей начальных классов повышением квалификации | F27: Комплексный план 3.06.26.docx | G27: D05 | H27: Сводные целевые показатели, позиция 7; строка определяется по формулировке «Охват учителей начальных классов повышением квалификации» | I27: Охват учителей начальных классов повышением квалификации | J27: Национальный/секторный | K27: Национальный/отраслевой показатель | L27: Требуется декомпозиция | M27: Указать после подтверждения индивидуального значения | N27: % | R27: 70 | S27: 80 | T27: 90 | W27: Сверено с первоисточником: формулировка реестра не подтверждена дословно; требуется уточнение
A28: 26 | B28: K145 | C28: Образование | D28: Показатель | E28: PhD на одного академического сотрудника | F28: THE анализ 2026.pdf | G28: D03 | H28: Стр. 25; строка определяется по формулировке «PhD на одного академического сотрудника» | I28: PhD на одного академического сотрудника | J28: Abai University | K28: Не является обязательным KPI | L28: Аналитический ориентир | N28: ед. | W28: Сверено с первоисточником
A29: 27 | B29: K146 | C29: Образование | D29: Показатель | E29: Соотношение студентов и преподавателей | F29: THE анализ 2026.pdf | G29: D03 | H29: Стр. 26; строка определяется по формулировке «Соотношение студентов и преподавателей» | I29: Соотношение студентов и преподавателей | J29: Abai University | K29: Не является обязательным KPI | L29: Аналитический ориентир | N29: ед. | W29: Сверено с первоисточником
A30: 28 | B30: K152 | C30: Образование | D30: Показатель | E30: Доля международных сотрудников | F30: THE анализ 2026.pdf | G30: D03 | H30: Стр. 63; строка определяется по формулировке «Доля международных сотрудников» | I30: Доля международных сотрудников | J30: Abai University | K30: Не является обязательным KPI | L30: Аналитический ориентир | N30: % | W30: Сверено с первоисточником: формулировка реестра не подтверждена дословно; требуется уточнение
A31: 29 | B31: K153 | C31: Образование | D31: Показатель | E31: Доля иностранных студентов | F31: THE анализ 2026.pdf | G31: D03 | H31: Стр. 63; строка определяется по формулировке «Доля иностранных студентов» | I31: Доля иностранных студентов | J31: Abai University | K31: Не является обязательным KPI | L31: Аналитический ориентир | N31: % | W31: Сверено с первоисточником
A32: 30 | B32: K155 | C32: Образование | D32: Показатель | E32: Голоса за преподавательскую репутацию | F32: THE анализ 2026.pdf | G32: D03 | H32: Стр. 73; строка определяется по формулировке «Голоса за преподавательскую репутацию» | I32: Голоса за преподавательскую репутацию | J32: Abai University | K32: Не является обязательным KPI | L32: Аналитический ориентир | N32: ед. | W32: Сверено с первоисточником: формулировка реестра не подтверждена дословно; требуется уточнение
A33: 31 | B33: K160 | C33: Образование | D33: Показатель | E33: Итоговый балл THE WUR 2031 — сценарий A | F33: THE анализ 2026.pdf | G33: D03 | H33: Итоговая симуляция; строка определяется по формулировке «Итоговый балл THE WUR 2031 — сценарий A» | I33: Итоговый балл THE WUR 2031 — сценарий A | J33: Abai University | K33: Не является обязательным KPI | L33: Аналитический ориентир | N33: балл | W33: Сверено с первоисточником: формулировка реестра не подтверждена дословно; требуется уточнение
A34: 32 | B34: K161 | C34: Образование | D34: Показатель | E34: Итоговый балл THE WUR 2031 — сценарий B | F34: THE анализ 2026.pdf | G34: D03 | H34: Итоговая симуляция; строка определяется по формулировке «Итоговый балл THE WUR 2031 — сценарий B» | I34: Итоговый балл THE WUR 2031 — сценарий B | J34: Abai University | K34: Не является обязательным KPI | L34: Аналитический ориентир | N34: балл | W34: Сверено с первоисточником: формулировка реестра не подтверждена дословно; требуется уточнение
A35: 33 | B35: K162 | C35: Образование | D35: Показатель | E35: Итоговый балл THE WUR 2031 — сценарий C | F35: THE анализ 2026.pdf | G35: D03 | H35: Итоговая симуляция; строка определяется по формулировке «Итоговый балл THE WUR 2031 — сценарий C» | I35: Итоговый балл THE WUR 2031 — сценарий C | J35: Abai University | K35: Не является обязательным KPI | L35: Аналитический ориентир | N35: балл | W35: Сверено с первоисточником: формулировка реестра не подтверждена дословно; требуется уточнение
A36: 34 | B36: M001 | C36: Образование | D36: Мероприятие | E36: Разработка единых требований к ОП педагогических направлении | F36: 0707_План действий -рус.docx | G36: D02 | H36: Таблица 1, строка 5; строка определяется по формулировке «Разработка единых требований к ОП педагогических направлении» | I36: Разработка единых требований к ОП педагогических направлении | J36: Организация/исполнитель по документу | K36: Требование/мероприятие применимо к ОВПО | L36: Прямая или совместная | W36: Сверено с первоисточником
A37: 35 | B37: M002 | C37: Образование | D37: Мероприятие | E37: Переход к двух этапному отбору абитуриентов на педагогические образовательные программы (ETS/AIT) | F37: 0707_План действий -рус.docx | G37: D02 | H37: Таблица 1, строка 6; строка определяется по формулировке «Переход к двух этапному отбору абитуриентов на педагогические образовательные программы (ETS/AIT)» | I37: Переход к двух этапному отбору абитуриентов на педагогические образовательные программы (ETS/AIT) | J37: Организация/исполнитель по документу | K37: Требование/мероприятие применимо к ОВПО | L37: Прямая или совместная | W37: Сверено с первоисточником
A38: 36 | B38: M003 | C38: Образование | D38: Мероприятие | E38: Выработка предложении по актуализации профессионального стандарта «Педагог» | F38: 0707_План действий -рус.docx | G38: D02 | H38: Таблица 1, строка 7; строка определяется по формулировке «Выработка предложении по актуализации профессионального стандарта «Педагог»» | I38: Выработка предложении по актуализации профессионального стандарта «Педагог» | J38: Организация/исполнитель по документу | K38: Требование/мероприятие применимо к ОВПО | L38: Прямая или совместная | W38: Сверено с первоисточником
A39: 37 | B39: M004 | C39: Образование | D39: Мероприятие | E39: Введение требований по AI-компетенциям выпускников педагогических образовательных программ | F39: 0707_План действий -рус.docx | G39: D02 | H39: Таблица 1, строка 8; строка определяется по формулировке «Введение требований по AI-компетенциям выпускников педагогических образовательных программ» | I39: Введение требований по AI-компетенциям выпускников педагогических образовательных программ | J39: Организация/исполнитель по документу | K39: Требование/мероприятие применимо к ОВПО | L39: Прямая или совместная | W39: Сверено с первоисточником
A40: 38 | B40: M005 | C40: Образование | D40: Мероприятие | E40: Модель школоцентричной подготовки педагогов | F40: 0707_План действий -рус.docx | G40: D02 | H40: Таблица 1, строка 9; строка определяется по формулировке «Модель школоцентричной подготовки педагогов» | I40: Модель школоцентричной подготовки педагогов | J40: Организация/исполнитель по документу | K40: Требование/мероприятие применимо к ОВПО | L40: Прямая или совместная | W40: Сверено с первоисточником
...

Sheet 02_Программа_развития
A1: Реестр KPI Программы развития, обеспечение Планом и факт за 2025 год
A2: № | B2: ID KPI | C2: Направление | D2: KPI Программы развития | E2: Единица | F2: 2023 | G2: 2024 | H2: План 2025 | I2: 2026 | J2: 2027 | K2: 2028 | L2: 2029 | M2: Ответственный по Программе | N2: Источник ID | O2: Точное место | P2: Связь с требованиями госорганов | Q2: ID внешних требований | R2: Количество мероприятий | S2: ID мероприятий | T2: Обеспечение Планом | U2: Факт 2025 | V2: Источник факта / расчёт | W2: Качество сопоставления факта | X2: Оценка 2025 | Y2: Отклонение от плана | Z2: Ограничение данных / аналитический комментарий
A3: 1 | B3: PRG001 | C3: Образование | D3: 1.1.1. Образовательные услуги в области высшего и послевузовского образования | E3: чел. | F3: 16151 | G3: 16700 | H3: 17400 | I3: 17700 | J3: 18100 | K3: 18300 | L3: 18500 | M3: Проректор по академической деятельности | N3: D20 | O3: Раздел 7 «Ключевые показатели деятельности», стр. 33–43; KPI 1.1.1; строка определяется по полному наименованию | P3: Прямая связь не установлена — собственная цель университета либо требуется дополнительное подтверждение | R3: 3 | S3: ACT001; ACT002; ACT003 | T3: Связанное мероприятие найдено; достаточность обеспечения оценивается по результату, сроку, ответственности и финансированию | U3: 20925 | V3: Отчёт о результатах деятельности за 2025 год, раздел 1; презентация, раздел 3: общий контингент — 20 925 человек | W3: Сопоставимо | X3: Цель перевыполнена | Y3: =IF(OR(H3="",U3=""),"",U3-H3) -> 3525 | Z3: В исходной таблице годы 2028 и 2029 продублированы техническими колонками; использованы первые значения для каждого года.
A4: 2 | B4: PRG002 | C4: Образование | D4: 1.1.2. Доля поступивших в ВУЗ, имеющих знаки «Алтын белгі», победителей международных олимпиад и конкурсов научных проектов последних трех лет, победителей президентской, республиканских олимпиад и конкурсов научных проектов текущего учебного года (награжденные дипломами первой, второй и третьей степени) от их общего количества | E4: % | F4: 8.6 | G4: 8.7 | H4: 8.8 | I4: 8.9 | J4: 9 | K4: 9.1 | L4: 9.2 | M4: Проректор по академической деятельности | N4: D20 | O4: Раздел 7 «Ключевые показатели деятельности», стр. 33–43; KPI 1.1.2; строка определяется по полному наименованию | P4: Прямая связь не установлена — собственная цель университета либо требуется дополнительное подтверждение | R4: 2 | S4: ACT004; ACT005 | T4: Связанное мероприятие найдено; достаточность обеспечения оценивается по результату, сроку, ответственности и финансированию | W4: Факт с формулой и единицей KPI в отчётах не найден | X4: Невозможно оценить — сопоставимый факт отсутствует | Z4: В исходной таблице годы 2028 и 2029 продублированы техническими колонками; использованы первые значения для каждого года.
A5: 3 | B5: PRG003 | C5: Образование | D5: 1.1.3. Доля ППС, прошедших повышение квалификации и зарубежную стажировку (в соответствии с коэффициентом для национальных университетов -1,5) | E5: % | F5: 50 | G5: 50 | H5: 50 | I5: 50 | J5: 50 | K5: 50 | L5: 50 | M5: Проректор по академической деятельности Проректор по стратегии и интернационализации | N5: D20 | O5: Раздел 7 «Ключевые показатели деятельности», стр. 33–43; KPI 1.1.3; строка определяется по полному наименованию | P5: Связь с внешними требованиями найдена | Q5: K102; Q009; Q041 | R5: 3 | S5: ACT006; ACT007; ACT008 | T5: Связанное мероприятие найдено; достаточность обеспечения оценивается по результату, сроку, ответственности и финансированию | W5: Факт с формулой и единицей KPI в отчётах не найден | X5: Невозможно оценить — сопоставимый факт отсутствует | Z5: В исходной таблице годы 2028 и 2029 продублированы техническими колонками; использованы первые значения для каждого года.
A6: 4 | B6: PRG004 | C6: Образование | D6: 1.1.4. Доля привлеченных работодателей, представителей бизнес-структур к учебному процессу от общего количества ППС | E6: % | F6: 16 | G6: 18 | H6: 20 | I6: 21 | J6: 23 | K6: 25 | L6: 27 | M6: Проректор по академическим вопросам | N6: D20 | O6: Раздел 7 «Ключевые показатели деятельности», стр. 33–43; KPI 1.1.4; строка определяется по полному наименованию | P6: Прямая связь не установлена — собственная цель университета либо требуется дополнительное подтверждение | R6: 3 | S6: ACT009; ACT010; ACT011 | T6: Связанное мероприятие найдено; достаточность обеспечения оценивается по результату, сроку, ответственности и финансированию | W6: Факт с формулой и единицей KPI в отчётах не найден | X6: Невозможно оценить — сопоставимый факт отсутствует | Z6: В исходной таблице годы 2028 и 2029 продублированы техническими колонками; использованы первые значения для каждого года.
A7: 5 | B7: PRG005 | C7: Образование | D7: 1.1.5. Прирост респондентов, привлеченных к участию в академических опросах | E7: чел. | F7: 400 | G7: 500 | H7: 600 | I7: 700 | J7: 800 | K7: 900 | L7: 1000 | M7: Проректор по стратегии и интернационализации Проректор по академической деятельности Директора институтов | N7: D20 | O7: Раздел 7 «Ключевые показатели деятельности», стр. 33–43; KPI 1.1.5; строка определяется по полному наименованию | P7: Прямая связь не установлена — собственная цель университета либо требуется дополнительное подтверждение | R7: 1 | S7: ACT012 | T7: Связанное мероприятие найдено; достаточность обеспечения оценивается по результату, сроку, ответственности и финансированию | W7: Факт с формулой и единицей KPI в отчётах не найден | X7: Невозможно оценить — сопоставимый факт отсутствует | Z7: В исходной таблице годы 2028 и 2029 продублированы техническими колонками; использованы первые значения для каждого года.
A8: 6 | B8: PRG006 | C8: Образование | D8: 1.1.6. Соотношение студентов и ППС | E8: ед. | F8: 16 | G8: 14 | H8: 14 | I8: 13 | J8: 13 | K8: 12 | L8: 12 | M8: Проректор по академической деятельности | N8: D20 | O8: Раздел 7 «Ключевые показатели деятельности», стр. 33–43; KPI 1.1.6; строка определяется по полному наименованию | P8: Связь с внешними требованиями найдена | Q8: K146 | R8: 0 | T8: Мероприятие для KPI не найдено | W8: Факт с формулой и единицей KPI в отчётах не найден | X8: Невозможно оценить — сопоставимый факт отсутствует | Z8: В отчёте есть численность студентов и ППС, но методика KPI не уточняет используемый состав ППС; расчёт без методики может быть некорректным. В исходной таблице годы 2028 и 2029 продублированы техническими колонками; использованы первые значения для каждого года.
A9: 7 | B9: PRG007 | C9: Образование | D9: 1.1.7. Количество штатных ППС | E9: чел. | F9: 859 | G9: 990 | H9: 1040 | I9: 1160 | J9: 1190 | K9: 1325 | L9: 1340 | M9: Руководитель аппарата ректора Проректор по академической деятельности | N9: D20 | O9: Раздел 7 «Ключевые показатели деятельности», стр. 33–43; KPI 1.1.7; строка определяется по полному наименованию | P9: Прямая связь не установлена — собственная цель университета либо требуется дополнительное подтверждение | R9: 1 | S9: ACT013 | T9: Связанное мероприятие найдено; достаточность обеспечения оценивается по результату, сроку, ответственности и финансированию | U9: 989 | V9: Отчёт о результатах деятельности за 2025 год, стр. 2–3; презентация, раздел 3: штатная численность ППС — 989 человек | W9: Сопоставимо | X9: Цель не достигнута | Y9: =IF(OR(H9="",U9=""),"",U9-H9) -> -51 | Z9: В исходной таблице годы 2028 и 2029 продублированы техническими колонками; использованы первые значения для каждого года.
A10: 8 | B10: PRG008 | C10: Образование | D10: 1.1.8. Остепенность ППС | E10: % | F10: 56 | G10: 56 | H10: 56 | I10: 56 | J10: 57 | K10: 58 | L10: 60 | M10: Руководитель аппарата ректора Проректор по академической деятельности | N10: D20 | O10: Раздел 7 «Ключевые показатели деятельности», стр. 33–43; KPI 1.1.8; строка определяется по полному наименованию | P10: Связь с внешними требованиями найдена | Q10: K145; Q043 | R10: 1 | S10: ACT014 | T10: Связанное мероприятие найдено; достаточность обеспечения оценивается по результату, сроку, ответственности и финансированию | U10: 57 | V10: Отчёт о результатах деятельности за 2025 год, стр. 3: ППС, имеющие учёную степень — 562 человека, или 57% | W10: Сопоставимо | X10: Цель перевыполнена | Y10: =IF(OR(H10="",U10=""),"",U10-H10) -> 1 | Z10: В исходной таблице годы 2028 и 2029 продублированы техническими колонками; использованы первые значения для каждого года.
A11: 9 | B11: PRG009 | C11: Образование | D11: 1.1.9. Доля документооборота в университете на государственном языке | E11: % | F11: 91 | G11: 91.5 | H11: 92 | I11: 92.5 | J11: 93 | K11: 93.5 | L11: 94 | M11: Руководитель аппарата ректора | N11: D20 | O11: Раздел 7 «Ключевые показатели деятельности», стр. 33–43; KPI 1.1.9; строка определяется по полному наименованию | P11: Прямая связь не установлена — собственная цель университета либо требуется дополнительное подтверждение | R11: 0 | T11: Мероприятие для KPI не найдено | W11: Факт с формулой и единицей KPI в отчётах не найден | X11: Невозможно оценить — сопоставимый факт отсутствует | Z11: В исходной таблице годы 2028 и 2029 продублированы техническими колонками; использованы первые значения для каждого года.
A12: 10 | B12: PRG010 | C12: Образование | D12: 1.2.1. Количество образовательных программ в рамках двудипломного образования с вузами-партнерами, в том числе из ТОП-700 рейтинга QS | E12: ед. | F12: 11 | G12: 11 | H12: 11 | I12: 12 | J12: 13 | K12: 13 | L12: 14 | M12: Проректор по стратегии и интернационализации Проректор по академической деятельности | N12: D20 | O12: Раздел 7 «Ключевые показатели деятельности», стр. 33–43; KPI 1.2.1; строка определяется по полному наименованию | P12: Связь с внешними требованиями найдена | Q12: K108 | R12: 3 | S12: ACT015; ACT016; ACT017 | T12: Связанное мероприятие найдено; достаточность обеспечения оценивается по результату, сроку, ответственности и финансированию | U12: 15 | V12: Отчёт о результатах деятельности за 2025 год, раздел 1; презентация, раздел 3: 15 двудипломных программ | W12: Сопоставимо | X12: Цель перевыполнена | Y12: =IF(OR(H12="",U12=""),"",U12-H12) -> 4 | Z12: В исходной таблице годы 2028 и 2029 продублированы техническими колонками; использованы первые значения для каждого года.
A13: 11 | B13: PRG011 | C13: Образование | D13: 1.2.2. Доля студентов, выехавших по программе академической мобильности за рубеж на срок не менее триместра, семестра, учебного года от общего количества студентов | E13: % | F13: 0.6 | H13: 0.68 | I13: 0.93 | J13: 1.05 | K13: 1.11 | L13: 1.23 | M13: Проректор по стратегии и интернационализации | N13: D20 | O13: Раздел 7 «Ключевые показатели деятельности», стр. 33–43; KPI 1.2.2; строка определяется по полному наименованию | P13: Прямая связь не установлена — собственная цель университета либо требуется дополнительное подтверждение | R13: 3 | S13: ACT018; ACT019; ACT020 | T13: Связанное мероприятие найдено; достаточность обеспечения оценивается по результату, сроку, ответственности и финансированию | U13: 1.52 | V13: Отчёт о результатах деятельности за 2025 год, раздел 3 «Интернационализация»: внешняя академическая мобильность — 280 человек, или 1,52% контингента бакалавриата | W13: Сопоставимо | X13: Цель перевыполнена | Y13: =IF(OR(H13="",U13=""),"",U13-H13) -> 0.84 | Z13: В исходной таблице годы 2028 и 2029 продублированы техническими колонками; использованы первые значения для каждого года.
A14: 12 | B14: PRG012 | C14: Образование | D14: 1.2.3. Доля ППС, преподающих на английском языке, от общего количества ППС | E14: % | F14: 18.7 | G14: 18.7 | H14: 18.8 | I14: 18.9 | J14: 19 | K14: 19.1 | L14: 19.2 | M14: Проректор по академической деятельности | N14: D20 | O14: Раздел 7 «Ключевые показатели деятельности», стр. 33–43; KPI 1.2.3; строка определяется по полному наименованию | P14: Прямая связь не установлена — собственная цель университета либо требуется дополнительное подтверждение | R14: 3 | S14: ACT021; ACT022; ACT023 | T14: Связанное мероприятие найдено; достаточность обеспечения оценивается по результату, сроку, ответственности и финансированию | U14: 21.12 | V14: Отчёт о результатах деятельности за 2025 год, раздел 3 «Интернационализация»: более 21,12% ППС ведут преподавание на английском языке | W14: Сопоставимо | X14: Цель перевыполнена | Y14: =IF(OR(H14="",U14=""),"",U14-H14) -> 2.32 | Z14: В исходной таблице годы 2028 и 2029 продублированы техническими колонками; использованы первые значения для каждого года.
A15: 13 | B15: PRG013 | C15: Образование | D15: 1.2.4. Доля иностранных студентов в вузе от общего количества студентов (в соответствии с коэффициентом для национальных университетов -1,5) | E15: % | F15: 3.5 | G15: 4.2 | H15: 4.3 | I15: 4.4 | J15: 4.6 | K15: 4.6 | L15: 5 | M15: Проректор по стратегии и интернационализации | N15: D20 | O15: Раздел 7 «Ключевые показатели деятельности», стр. 33–43; KPI 1.2.4; строка определяется по полному наименованию | P15: Связь с внешними требованиями найдена | Q15: K153 | R15: 3 | S15: ACT024; ACT025; ACT026 | T15: Связанное мероприятие найдено; достаточность обеспечения оценивается по результату, сроку, ответственности и финансированию | U15: 9.72 | V15: Отчёт о результатах деятельности за 2025 год, раздел 3 «Интернационализация»: доля иностранных студентов — 9,72%, 1 936 человек | W15: Сопоставимо | X15: Цель перевыполнена | Y15: =IF(OR(H15="",U15=""),"",U15-H15) -> 5.42 | Z15: Код уточнён по контрольному перечню 65 KPI: 1.2.4.
A16: 14 | B16: PRG014 | C16: Образование | D16: 1.2.5. Доля привлеченных зарубежных экспертов к преподавательской деятельности | E16: % | F16: 1.6 | G16: 1.7 | H16: 1.8 | I16: 1.9 | J16: 2 | K16: 2.1 | L16: 2.3 | M16: Проректор по академической деятельности Проректор по стратегии и интернационализации | N16: D20 | O16: Раздел 7 «Ключевые показатели деятельности», стр. 33–43; KPI 1.2.5; строка определяется по полному наименованию | P16: Прямая связь не установлена — собственная цель университета либо требуется дополнительное подтверждение | R16: 5 | S16: ACT027; ACT028; ACT029; ACT030; ACT031 | T16: Связанное мероприятие найдено; достаточность обеспечения оценивается по результату, сроку, ответственности и финансированию | W16: Факт с формулой и единицей KPI в отчётах не найден | X16: Невозможно оценить — сопоставимый факт отсутствует | Z16: В отчёте указано 51 зарубежный учёный, но не подтверждено, что все они привлечены именно к преподавательской деятельности. В исходной таблице годы 2028 и 2029 продублированы техническими колонками; использованы первые значения для каждого года.
A17: 15 | B17: PRG015 | C17: Образование | D17: 1.2.6. Количество международных образовательных программ | E17: ед. | F17: 2 | G17: 2 | H17: 2 | I17: 2 | J17: 3 | K17: 3 | L17: 3 | M17: Проректор по академической деятельности Проректор по стратегии и интернационализации | N17: D20 | O17: Раздел 7 «Ключевые показатели деятельности», стр. 33–43; KPI 1.2.6; строка определяется по полному наименованию | P17: Прямая связь не установлена — собственная цель университета либо требуется дополнительное подтверждение | R17: 2 | S17: ACT032; ACT033 | T17: Связанное мероприятие найдено; достаточность обеспечения оценивается по результату, сроку, ответственности и финансированию | U17: 10 | V17: Отчёт о результатах деятельности за 2025 год, раздел 3 «Интернационализация»: количество международных образовательных проектов — 10 | W17: Сопоставимо при подтверждении, что термин «проект» соответствует KPI «программа» | X17: Цель перевыполнена | Y17: =IF(OR(H17="",U17=""),"",U17-H17) -> 8 | Z17: В исходной таблице годы 2028 и 2029 продублированы техническими колонками; использованы первые значения для каждого года.
A18: 16 | B18: PRG016 | C18: Образование | D18: 1.2.7. Позиция вуза в рейтинге QS-WUR, в том числе ТОП-700 | E18: место | F18: 690 | G18: 680 | H18: 680 | I18: 670 | J18: 660 | K18: 650 | L18: 640 | M18: Проректор по стратегии и интернационализации | N18: D20 | O18: Раздел 7 «Ключевые показатели деятельности», стр. 33–43; KPI 1.2.7; строка определяется по полному наименованию | P18: Связь с внешними требованиями найдена | Q18: K002; K004; K105; K106 | R18: 1 | S18: ACT034 | T18: Связанное мероприятие найдено; достаточность обеспечения оценивается по результату, сроку, ответственности и финансированию | W18: Факт с формулой и единицей KPI в отчётах не найден | X18: Невозможно оценить — сопоставимый факт отсутствует | Z18: В исходной таблице годы 2028 и 2029 продублированы техническими колонками; использованы первые значения для каждого года.
A19: 17 | B19: PRG017 | C19: Образование | D19: 1.2.8. Количество программ, вошедших в QS BY SUBJECT, в том числе ТОП-100 | E19: ед. | F19: 2 | G19: 2 | H19: 2 | I19: 2 | J19: 3 | K19: 3 | L19: 3 | M19: Проректор по стратегии и интернационализации | N19: D20 | O19: Раздел 7 «Ключевые показатели деятельности», стр. 33–43; KPI 1.2.8; строка определяется по полному наименованию | P19: Прямая связь не установлена — собственная цель университета либо требуется дополнительное подтверждение | R19: 2 | S19: ACT035; ACT036 | T19: Связанное мероприятие найдено; достаточность обеспечения оценивается по результату, сроку, ответственности и финансированию | W19: Факт с формулой и единицей KPI в отчётах не найден | X19: Невозможно оценить — сопоставимый факт отсутствует | Z19: В исходной таблице годы 2028 и 2029 продублированы техническими колонками; использованы первые значения для каждого года.
A20: 18 | B20: PRG018 | C20: Образование | D20: 1.3.1. Доля образовательных программ, при реализации которых используются мировые цифровые библиотеки | E20: % | F20: 85 | G20: 86 | H20: 87 | I20: 88 | J20: 88 | K20: 89 | L20: 90 | M20: Проректор по академической деятельности | N20: D20 | O20: Раздел 7 «Ключевые показатели деятельности», стр. 33–43; KPI 1.3.1; строка определяется по полному наименованию | P20: Прямая связь не установлена — собственная цель университета либо требуется дополнительное подтверждение | R20: 3 | S20: ACT037; ACT038; ACT039 | T20: Связанное мероприятие найдено; достаточность обеспечения оценивается по результату, сроку, ответственности и финансированию | W20: Факт с формулой и единицей KPI в отчётах не найден | X20: Невозможно оценить — сопоставимый факт отсутствует | Z20: В исходной таблице годы 2028 и 2029 продублированы техническими колонками; использованы первые значения для каждого года.
A21: 19 | B21: PRG019 | C21: Образование | D21: 1.3.2. Доля студентов, использующих мировые цифровые библиотеки в учебном процессе | E21: % | F21: 80 | G21: 82 | H21: 84 | I21: 86 | J21: 88 | K21: 90 | L21: 92 | M21: Проректор по академической деятельности | N21: D20 | O21: Раздел 7 «Ключевые показатели деятельности», стр. 33–43; KPI 1.3.2; строка определяется по полному наименованию | P21: Прямая связь не установлена — собственная цель университета либо требуется дополнительное подтверждение | R21: 2 | S21: ACT040; ACT041 | T21: Связанное мероприятие найдено; достаточность обеспечения оценивается по результату, сроку, ответственности и финансированию | W21: Факт с формулой и единицей KPI в отчётах не найден | X21: Невозможно оценить — сопоставимый факт отсутствует | Z21: В исходной таблице годы 2028 и 2029 продублированы техническими колонками; использованы первые значения для каждого года.
A22: 20 | B22: PRG020 | C22: Образование | D22: 1.3.3. Количество образовательных программ, использующих онлайн-курсы, в том числе платформы Coursera | E22: ед. | F22: 51 | G22: 54 | H22: 57 | I22: 60 | J22: 62 | K22: 65 | L22: 67 | M22: Проректор по академической деятельности | N22: D20 | O22: Раздел 7 «Ключевые показатели деятельности», стр. 33–43; KPI 1.3.3; строка определяется по полному наименованию | P22: Прямая связь не установлена — собственная цель университета либо требуется дополнительное подтверждение | R22: 2 | S22: ACT042; ACT043 | T22: Связанное мероприятие найдено; достаточность обеспечения оценивается по результату, сроку, ответственности и финансированию | W22: Факт с формулой и единицей KPI в отчётах не найден | X22: Невозможно оценить — сопоставимый факт отсутствует | Z22: В отчёте указаны 2 собственных MOOC на Coursera, но KPI измеряет количество образовательных программ, использующих онлайн-курсы. В исходной таблице годы 2028 и 2029 продублированы техническими колонками; использованы первые значения для каждого года.
A23: 21 | B23: PRG021 | C23: Образование | D23: 1.3.4. Доля обучающихся, прошедших онлайн обучение, в том числе на платформе Coursera | E23: % | F23: 9 | G23: 10 | H23: 11 | I23: 12 | J23: 13 | K23: 14 | L23: 15 | M23: Проректор по академической деятельности | N23: D20 | O23: Раздел 7 «Ключевые показатели деятельности», стр. 33–43; KPI 1.3.4; строка определяется по полному наименованию | P23: Прямая связь не установлена — собственная цель университета либо требуется дополнительное подтверждение | R23: 0 | T23: Мероприятие для KPI не найдено | W23: Факт с формулой и единицей KPI в отчётах не найден | X23: Невозможно оценить — сопоставимый факт отсутствует | Z23: В исходной таблице годы 2028 и 2029 продублированы техническими колонками; использованы первые значения для каждого года.
A24: 22 | B24: PRG022 | C24: Образование | D24: 1.3.5 Доля обученных студентов латинской графике казахского языка от общего контингента обучающихся бакалавриата | E24: % | G24: 25 | H24: 35 | I24: 45 | J24: 55 | K24: 60 | L24: 70 | M24: Проректор по академической деятельности | N24: D20 | O24: Раздел 7 «Ключевые показатели деятельности», стр. 33–43; KPI 1.3.5; строка определяется по полному наименованию | P24: Прямая связь не установлена — собственная цель университета либо требуется дополнительное подтверждение | R24: 1 | S24: ACT137 | T24: Связанное мероприятие найдено; достаточность обеспечения оценивается по результату, сроку, ответственности и финансированию | W24: Факт с формулой и единицей KPI в отчётах не найден | X24: Невозможно оценить — сопоставимый факт отсутствует | Z24: В исходной таблице годы 2028 и 2029 продублированы техническими колонками; использованы первые значения для каждого года.
A25: 23 | B25: PRG023 | C25: Образование | D25: 2.1.1. Уровень созданных условий для инклюзивного образования в университете | E25: % | F25: 40 | G25: 42 | H25: 43 | I25: 44 | J25: 45 | K25: 45 | L25: 45 | M25: Проректор по академической деятельности | N25: D20 | O25: Раздел 7 «Ключевые показатели деятельности», стр. 33–43; KPI 2.1.1; строка определяется по полному наименованию | P25: Связь с внешними требованиями найдена | Q25: K006; K109; Q006 | R25: 2 | S25: ACT044; ACT045 | T25: Связанное мероприятие найдено; достаточность обеспечения оценивается по результату, сроку, ответственности и финансированию | W25: Факт с формулой и единицей KPI в отчётах не найден | X25: Невозможно оценить — сопоставимый факт отсутствует | Z25: В исходной таблице годы 2028 и 2029 продублированы техническими колонками; использованы первые значения для каждого года.
A26: 24 | B26: PRG024 | C26: Образование | D26: 2.1.2. Количество привлечённых к работе по развитию инклюзивного образования неправительственных организаций, общественных фондов и объединений | E26: ед. | F26: 3 | G26: 3 | H26: 3 | I26: 3 | J26: 3 | K26: 3 | L26: 3 | M26: Проректор по академической деятельности; директор Института педагогики и психологии | N26: D20 | O26: Раздел 7 «Ключевые показатели деятельности», стр. 33–43; KPI 2.1.2; строка определяется по полному наименованию | P26: Прямая связь не установлена — собственная цель университета либо требуется дополнительное подтверждение | R26: 1 | S26: ACT046 | T26: Связанное мероприятие найдено; достаточность обеспечения оценивается по результату, сроку, ответственности и финансированию | W26: Факт с формулой и единицей KPI в отчётах не найден | X26: Невозможно оценить — сопоставимый факт отсутствует | Z26: Показатель отсутствовал в предыдущей версии Excel; восстановлен по утверждённой Программе и контрольному перечню из 65 KPI.
A27: 25 | B27: PRG025 | C27: Образование | D27: 2.2.1. Количество слушателей по программам Серебряного университета | E27: чел. | G27: 10 | H27: 20 | I27: 25 | J27: 30 | K27: 35 | L27: 40 | M27: Проректор по академической деятельности | N27: D20 | O27: Раздел 7 «Ключевые показатели деятельности», стр. 33–43; KPI 2.2.1; строка определяется по полному наименованию | P27: Прямая связь не установлена — собственная цель университета либо требуется дополнительное подтверждение | R27: 2 | S27: ACT047; ACT048 | T27: Связанное мероприятие найдено; достаточность обеспечения оценивается по результату, сроку, ответственности и финансированию | W27: Факт с формулой и единицей KPI в отчётах не найден | X27: Невозможно оценить — сопоставимый факт отсутствует | Z27: В презентации указано 236 слушателей Серебряного университета за два года; показатель 2025 года отдельно не выделен. В исходной таблице годы 2028 и 2029 продублированы техническими колонками; использованы первые значения для каждого года.
A28: 26 | B28: PRG026 | C28: Образование | D28: 2.2.2. Количество слушателей по программам неформального образования (кроме Серебряного университета) | E28: чел. | G28: 350 | H28: 350 | I28: 400 | J28: 400 | K28: 450 | L28: 500 | M28: Проректор по академической деятельности | N28: D20 | O28: Раздел 7 «Ключевые показатели деятельности», стр. 33–43; KPI 2.2.2; строка определяется по полному наименованию | P28: Прямая связь не установлена — собственная цель университета либо требуется дополнительное подтверждение | R28: 2 | S28: ACT049; ACT050 | T28: Связанное мероприятие найдено; достаточность обеспечения оценивается по результату, сроку, ответственности и финансированию | W28: Факт с формулой и единицей KPI в отчётах не найден | X28: Невозможно оценить — сопоставимый факт отсутствует | Z28: В исходной таблице годы 2028 и 2029 продублированы техническими колонками; использованы первые значения для каждого года.
A29: 27 | B29: PRG027 | C29: Образование | D29: 2.2.3. Количество слушателей по программам педагогической переподготовки | E29: чел. | F29: 100 | G29: 120 | H29: 130 | I29: 140 | J29: 150 | K29: 160 | L29: 170 | M29: Проректор по академической деятельности | N29: D20 | O29: Раздел 7 «Ключевые показатели деятельности», стр. 33–43; KPI 2.2.3; строка определяется по полному наименованию | P29: Прямая связь не установлена — собственная цель университета либо требуется дополнительное подтверждение | R29: 3 | S29: ACT051; ACT052; ACT053 | T29: Связанное мероприятие найдено; достаточность обеспечения оценивается по результату, сроку, ответственности и финансированию | W29: Факт с формулой и единицей KPI в отчётах не найден | X29: Невозможно оценить — сопоставимый факт отсутствует | Z29: В исходной таблице годы 2028 и 2029 продублированы техническими колонками; использованы первые значения для каждого года.
A30: 28 | B30: PRG028 | C30: Образование | D30: 2.3.1. Результаты трудоустройства выпускников в первый год после окончания вуза | E30: % | F30: 95 | G30: 95 | H30: 95 | I30: 95 | J30: 96 | K30: 96 | L30: 96 | M30: Проректор по академической деятельности | N30: D20 | O30: Раздел 7 «Ключевые показатели деятельности», стр. 33–43; KPI 2.3.1; строка определяется по полному наименованию | P30: Связь с внешними требованиями найдена | Q30: K008; K103; K107; Q019 | R30: 3 | S30: ACT054; ACT055; ACT056 | T30: Связанное мероприятие найдено; достаточность обеспечения оценивается по результату, сроку, ответственности и финансированию | U30: 95 | V30: Отчёт о результатах деятельности за 2025 год; презентация, раздел 3: трудоустройство выпускников в первый год — 95% | W30: Сопоставимо | X30: Цель достигнута | Y30: =IF(OR(H30="",U30=""),"",U30-H30) -> 0 | Z30: В исходной таблице годы 2028 и 2029 продублированы техническими колонками; использованы первые значения для каждого года.
A31: 29 | B31: PRG029 | C31: Образование | D31: 2.3.2. Прирост респондентов, привлеченных к участию в репутационных опросах работодателей | E31: чел. | F31: 250 | G31: 300 | H31: 350 | I31: 400 | J31: 450 | K31: 500 | L31: 550 | M31: Проректор по академической деятельности Директора институтов | N31: D20 | O31: Раздел 7 «Ключевые показатели деятельности», стр. 33–43; KPI 2.3.2; строка определяется по полному наименованию | P31: Прямая связь не установлена — собственная цель университета либо требуется дополнительное подтверждение | R31: 1 | S31: ACT057 | T31: Связанное мероприятие найдено; достаточность обеспечения оценивается по результату, сроку, ответственности и финансированию | W31: Факт с формулой и единицей KPI в отчётах не найден | X31: Невозможно оценить — сопоставимый факт отсутствует | Z31: В исходной таблице годы 2028 и 2029 продублированы техническими колонками; использованы первые значения для каждого года.
A32: 30 | B32: PRG030 | C32: Образование | D32: 2.3.3. Степень удовлетворенности обучающихся качеством образовательных услуг и образовательной экосистемой | E32: % | F32: 70 | G32: 71 | H32: 72 | I32: 75 | J32: 76 | K32: 78 | L32: 80 | M32: Офис институциональной эффективности | N32: D20 | O32: Раздел 7 «Ключевые показатели деятельности», стр. 33–43; KPI 2.3.3; строка определяется по полному наименованию | P32: Прямая связь не установлена — собственная цель университета либо требуется дополнительное подтверждение | R32: 2 | S32: ACT058; ACT059 | T32: Связанное мероприятие найдено; достаточность обеспечения оценивается по результату, сроку, ответственности и финансированию | W32: Факт с формулой и единицей KPI в отчётах не найден | X32: Невозможно оценить — сопоставимый факт отсутствует | Z32: В исходной таблице годы 2028 и 2029 продублированы техническими колонками; использованы первые значения для каждого года.
A33: 31 | B33: PRG031 | C33: Наука | D33: 1.1.1. Количество статей и обзоров ППС, работников университета в высокорейтинговых изданиях Q1, Q2 Journal Citation Reports JCR, WoS, Scopus | E33: ед. | F33: 110 | G33: 115 | H33: 120 | I33: 125 | J33: 130 | K33: 135 | L33: 140 | M33: Проректор по исследовательской деятельности и инновации | N33: D20 | O33: Раздел 7 «Ключевые показатели деятельности», стр. 33–43; KPI 1.1.1; строка определяется по полному наименованию | P33: Связь с внешними требованиями найдена | Q33: K016; K111; K147; K148; K149 | R33: 2 | S33: ACT060; ACT061 | T33: Связанное мероприятие найдено; достаточность обеспечения оценивается по результату, сроку, ответственности и финансированию | W33: Факт с формулой и единицей KPI в отчётах не найден | X33: Невозможно оценить — сопоставимый факт отсутствует | Z33: В отчёте приведено общее количество публикаций Scopus и Web of Science, но не выделены статьи Q1–Q2 по формуле KPI. В исходной таблице годы 2028 и 2029 продублированы техническими колонками; использованы первые значения для каждого года.
A34: 32 | B34: PRG032 | C34: Наука | D34: 1.1.2. Цитируемость на одного работника | E34: % | F34: 1.2 | G34: 1.2 | H34: 1.2 | I34: 1.3 | J34: 1.3 | K34: 1.4 | L34: 1.5 | M34: Проректор по исследовательской деятельности и инновации | N34: D20 | O34: Раздел 7 «Ключевые показатели деятельности», стр. 33–43; KPI 1.1.2; строка определяется по полному наименованию | P34: Прямая связь не установлена — собственная цель университета либо требуется дополнительное подтверждение | R34: 1 | S34: ACT138 | T34: Связанное мероприятие найдено; достаточность обеспечения оценивается по результату, сроку, ответственности и финансированию | W34: Факт с формулой и единицей KPI в отчётах не найден | X34: Невозможно оценить — сопоставимый факт отсутствует | Z34: В исходной таблице годы 2028 и 2029 продублированы техническими колонками; использованы первые значения для каждого года.
